[2024-05-09T20:04:37.593+0000] {taskinstance.py:1159} INFO - Dependencies all met for dep_context=non-requeueable deps ti=<TaskInstance: pyspark_dag.pyspark_consumer scheduled__2024-05-08T20:03:57.803650+00:00 [queued]>
[2024-05-09T20:04:37.608+0000] {taskinstance.py:1159} INFO - Dependencies all met for dep_context=requeueable deps ti=<TaskInstance: pyspark_dag.pyspark_consumer scheduled__2024-05-08T20:03:57.803650+00:00 [queued]>
[2024-05-09T20:04:37.609+0000] {taskinstance.py:1361} INFO - Starting attempt 2 of 2
[2024-05-09T20:04:37.637+0000] {taskinstance.py:1382} INFO - Executing <Task(DockerOperator): pyspark_consumer> on 2024-05-08 20:03:57.803650+00:00
[2024-05-09T20:04:37.646+0000] {standard_task_runner.py:57} INFO - Started process 905 to run task
[2024-05-09T20:04:37.652+0000] {standard_task_runner.py:84} INFO - Running: ['***', 'tasks', 'run', 'pyspark_dag', 'pyspark_consumer', 'scheduled__2024-05-08T20:03:57.803650+00:00', '--job-id', '6', '--raw', '--subdir', 'DAGS_FOLDER/dag_spark.py', '--cfg-path', '/tmp/tmp1k8laloo']
[2024-05-09T20:04:37.656+0000] {standard_task_runner.py:85} INFO - Job 6: Subtask pyspark_consumer
[2024-05-09T20:04:37.733+0000] {task_command.py:416} INFO - Running <TaskInstance: pyspark_dag.pyspark_consumer scheduled__2024-05-08T20:03:57.803650+00:00 [running]> on host 77df0b9af859
[2024-05-09T20:04:37.945+0000] {taskinstance.py:1662} INFO - Exporting env vars: AIRFLOW_CTX_DAG_OWNER='***' AIRFLOW_CTX_DAG_ID='pyspark_dag' AIRFLOW_CTX_TASK_ID='pyspark_consumer' AIRFLOW_CTX_EXECUTION_DATE='2024-05-08T20:03:57.803650+00:00' AIRFLOW_CTX_TRY_NUMBER='2' AIRFLOW_CTX_DAG_RUN_ID='scheduled__2024-05-08T20:03:57.803650+00:00'
[2024-05-09T20:04:37.971+0000] {docker.py:343} INFO - Starting docker container from image wba-demo/spark:latest
[2024-05-09T20:04:37.979+0000] {docker.py:351} WARNING - Using remote engine or docker-in-docker and mounting temporary volume from host is not supported. Falling back to `mount_tmp_dir=False` mode. You can set `mount_tmp_dir` parameter to False to disable mounting and remove the warning
[2024-05-09T20:04:38.112+0000] {taskinstance.py:1937} ERROR - Task failed with exception
Traceback (most recent call last):
  File "/home/airflow/.local/lib/python3.8/site-packages/docker/api/client.py", line 268, in _raise_for_status
    response.raise_for_status()
  File "/home/airflow/.local/lib/python3.8/site-packages/requests/models.py", line 1021, in raise_for_status
    raise HTTPError(http_error_msg, response=self)
requests.exceptions.HTTPError: 400 Client Error: Bad Request for url: http://docker-proxy:2375/v1.43/containers/create

The above exception was the direct cause of the following exception:

Traceback (most recent call last):
  File "/home/airflow/.local/lib/python3.8/site-packages/airflow/providers/docker/operators/docker.py", line 348, in _run_image
    return self._run_image_with_mounts([*self.mounts, tmp_mount], add_tmp_variable=True)
  File "/home/airflow/.local/lib/python3.8/site-packages/airflow/providers/docker/operators/docker.py", line 375, in _run_image_with_mounts
    self.container = self.cli.create_container(
  File "/home/airflow/.local/lib/python3.8/site-packages/docker/api/container.py", line 431, in create_container
    return self.create_container_from_config(config, name, platform)
  File "/home/airflow/.local/lib/python3.8/site-packages/docker/api/container.py", line 448, in create_container_from_config
    return self._result(res, True)
  File "/home/airflow/.local/lib/python3.8/site-packages/docker/api/client.py", line 274, in _result
    self._raise_for_status(response)
  File "/home/airflow/.local/lib/python3.8/site-packages/docker/api/client.py", line 270, in _raise_for_status
    raise create_api_error_from_http_exception(e) from e
  File "/home/airflow/.local/lib/python3.8/site-packages/docker/errors.py", line 39, in create_api_error_from_http_exception
    raise cls(e, response=response, explanation=explanation) from e
docker.errors.APIError: 400 Client Error for http://docker-proxy:2375/v1.43/containers/create: Bad Request ("invalid mount config for type "bind": bind source path does not exist: /tmp/airflowtmp_fx1ckls")

During handling of the above exception, another exception occurred:

Traceback (most recent call last):
  File "/home/airflow/.local/lib/python3.8/site-packages/docker/api/client.py", line 268, in _raise_for_status
    response.raise_for_status()
  File "/home/airflow/.local/lib/python3.8/site-packages/requests/models.py", line 1021, in raise_for_status
    raise HTTPError(http_error_msg, response=self)
requests.exceptions.HTTPError: 404 Client Error: Not Found for url: http://docker-proxy:2375/v1.43/containers/9c6a34ca6b2a7973b6610a232728a3e2b6267876b76d30656d6ffca34f2f77b1/start

The above exception was the direct cause of the following exception:

Traceback (most recent call last):
  File "/home/airflow/.local/lib/python3.8/site-packages/airflow/providers/docker/operators/docker.py", line 486, in execute
    return self._run_image()
  File "/home/airflow/.local/lib/python3.8/site-packages/airflow/providers/docker/operators/docker.py", line 357, in _run_image
    return self._run_image_with_mounts(self.mounts, add_tmp_variable=False)
  File "/home/airflow/.local/lib/python3.8/site-packages/airflow/providers/docker/operators/docker.py", line 407, in _run_image_with_mounts
    self.cli.start(self.container["Id"])
  File "/home/airflow/.local/lib/python3.8/site-packages/docker/utils/decorators.py", line 19, in wrapped
    return f(self, resource_id, *args, **kwargs)
  File "/home/airflow/.local/lib/python3.8/site-packages/docker/api/container.py", line 1127, in start
    self._raise_for_status(res)
  File "/home/airflow/.local/lib/python3.8/site-packages/docker/api/client.py", line 270, in _raise_for_status
    raise create_api_error_from_http_exception(e) from e
  File "/home/airflow/.local/lib/python3.8/site-packages/docker/errors.py", line 39, in create_api_error_from_http_exception
    raise cls(e, response=response, explanation=explanation) from e
docker.errors.NotFound: 404 Client Error for http://docker-proxy:2375/v1.43/containers/9c6a34ca6b2a7973b6610a232728a3e2b6267876b76d30656d6ffca34f2f77b1/start: Not Found ("network wba-network not found")
[2024-05-09T20:04:38.130+0000] {taskinstance.py:1400} INFO - Marking task as FAILED. dag_id=pyspark_dag, task_id=pyspark_consumer, execution_date=20240508T200357, start_date=20240509T200437, end_date=20240509T200438
[2024-05-09T20:04:38.157+0000] {standard_task_runner.py:104} ERROR - Failed to execute job 6 for task pyspark_consumer (404 Client Error for http://docker-proxy:2375/v1.43/containers/9c6a34ca6b2a7973b6610a232728a3e2b6267876b76d30656d6ffca34f2f77b1/start: Not Found ("network wba-network not found"); 905)
[2024-05-09T20:04:38.203+0000] {local_task_job_runner.py:228} INFO - Task exited with return code 1
[2024-05-09T20:04:38.226+0000] {taskinstance.py:2778} INFO - 0 downstream tasks scheduled from follow-on schedule check
